{"ip": "200.17.112.121", "ErrorMessage": "Traceback (most recent call last):\n  File \"temp2017.py\", line 1, in <module>\n    dado = int(input ())\nValueError: invalid literal for int() with base 10: '4.0'\n", "LastIsEmpty": false, "ErrorType": "ValueError", "CoverageInfo": [5, 4, 0, 0, 20, "2-5"], "CorrectInputs": [[["4"], 1501092184]], "BadInput": ["4.0"], "UniqueId": "c2dd44e9-d115-4404-d297-f4df8535ba90_0", "TimeStamp": 1501092175}